
The following modules were not unloaded:
   (Use "module --force purge" to unload all):

  1) XALT/minimal   2) slurm   3) NeSI
2024-04-16 13:59:06.300498: E tensorflow/compiler/xla/stream_executor/cuda/cuda_dnn.cc:9342] Unable to register cuDNN factory: Attempting to register factory for plugin cuDNN when one has already been registered
2024-04-16 13:59:06.300581: E tensorflow/compiler/xla/stream_executor/cuda/cuda_fft.cc:609] Unable to register cuFFT factory: Attempting to register factory for plugin cuFFT when one has already been registered
2024-04-16 13:59:06.300621: E tensorflow/compiler/xla/stream_executor/cuda/cuda_blas.cc:1518] Unable to register cuBLAS factory: Attempting to register factory for plugin cuBLAS when one has already been registered
2024-04-16 13:59:06.313682: I tensorflow/core/platform/cpu_feature_guard.cc:182] This TensorFlow binary is optimized to use available CPU instructions in performance-critical operations.
To enable the following instructions: AVX2 FMA, in other operations, rebuild TensorFlow with the appropriate compiler flags.
2024-04-16 13:59:12.220297: I tensorflow/core/common_runtime/gpu/gpu_device.cc:1886] Created device /job:localhost/replica:0/task:0/device:GPU:0 with 38298 MB memory:  -> device: 0, name: NVIDIA A100-PCIE-40GB, pci bus id: 0000:05:00.0, compute capability: 8.0
1 Physical GPUs, 1 Logical GPUs
Traceback (most recent call last):
  File "/scale_wlg_persistent/filesets/project/uoa00195/EMRI_generation/EMRI_signal_detection/plot_reconstructions.py", line 69, in <module>
    y_pred_EMRIs= model.predict(X_EMRIs)
  File "/nesi/project/uoa00195/conda_envs/few_env_py3_10/lib/python3.10/site-packages/keras/src/utils/traceback_utils.py", line 70, in error_handler
    raise e.with_traceback(filtered_tb) from None
  File "/dev/shm/jobs/45639289/__autograph_generated_fileh1su47hl.py", line 15, in tf__predict_function
    retval_ = ag__.converted_call(ag__.ld(step_function), (ag__.ld(self), ag__.ld(iterator)), None, fscope)
ValueError: in user code:

    File "/nesi/project/uoa00195/conda_envs/few_env_py3_10/lib/python3.10/site-packages/keras/src/engine/training.py", line 2416, in predict_function  *
        return step_function(self, iterator)
    File "/nesi/project/uoa00195/conda_envs/few_env_py3_10/lib/python3.10/site-packages/keras/src/engine/training.py", line 2401, in step_function  **
        outputs = model.distribute_strategy.run(run_step, args=(data,))
    File "/nesi/project/uoa00195/conda_envs/few_env_py3_10/lib/python3.10/site-packages/keras/src/engine/training.py", line 2389, in run_step  **
        outputs = model.predict_step(data)
    File "/nesi/project/uoa00195/conda_envs/few_env_py3_10/lib/python3.10/site-packages/keras/src/engine/training.py", line 2357, in predict_step
        return self(x, training=False)
    File "/nesi/project/uoa00195/conda_envs/few_env_py3_10/lib/python3.10/site-packages/keras/src/utils/traceback_utils.py", line 70, in error_handler
        raise e.with_traceback(filtered_tb) from None
    File "/nesi/project/uoa00195/conda_envs/few_env_py3_10/lib/python3.10/site-packages/keras/src/engine/input_spec.py", line 298, in assert_input_compatibility
        raise ValueError(

    ValueError: Input 0 of layer "sequential" is incompatible with the layer: expected shape=(None, 8388608, 2), found shape=(None, 4194304, 2)

